Workbook

Sheet Raw_Data
A1: 🇮🇳 INDIA POPULATION DATA ANALYSIS | State & UT wise Census Data | 2001 – 2021
A2: Source: Census of India 2001, 2011 | 2021 Projected | 36 States & Union Territories
A3: State / UT | B3: Region | C3: Category | D3: Area (km²) | E3: Population 2001 | F3: Population 2011 | G3: Population 2021* | H3: Urban Pop 2011 | I3: Rural Pop 2011 | J3: Male Pop 2011 | K3: Female Pop 2011 | L3: Density 2011 | M3: Literacy % | N3: Growth Rate % | O3: HDI Score | P3: Capital City
A4: Uttar Pradesh | B4: North | C4: State | D4: 240928 | E4: 166197921 | F4: 199812341 | G4: 235000000 | H4: 44495063 | I4: 155317278 | J4: 104480510 | K4: 95331831 | L4: 829 | M4: 67.7 | N4: 20.2 | O4: 0.596 | P4: Lucknow
A5: Maharashtra | B5: West | C5: State | D5: 307713 | E5: 96878627 | F5: 112374333 | G5: 126000000 | H5: 50827531 | I5: 61546802 | J5: 58243056 | K5: 54131277 | L5: 365 | M5: 82.9 | N5: 16 | O5: 0.752 | P5: Mumbai
A6: Bihar | B6: East | C6: State | D6: 94163 | E6: 82998509 | F6: 104099452 | G6: 121000000 | H6: 11729609 | I6: 92369843 | J6: 54278157 | K6: 49821295 | L6: 1106 | M6: 63.8 | N6: 25.4 | O6: 0.569 | P6: Patna
A7: West Bengal | B7: East | C7: State | D7: 88752 | E7: 80176197 | F7: 91276115 | G7: 100000000 | H7: 29134060 | I7: 62142055 | J7: 46809027 | K7: 44467088 | L7: 1028 | M7: 77.1 | N7: 13.9 | O7: 0.682 | P7: Kolkata
A8: Madhya Pradesh | B8: Central | C8: State | D8: 308252 | E8: 60348023 | F8: 72626809 | G8: 84000000 | H8: 20059666 | I8: 52567143 | J8: 37612306 | K8: 35014503 | L8: 236 | M8: 70.6 | N8: 20.3 | O8: 0.649 | P8: Bhopal
A9: Rajasthan | B9: North | C9: State | D9: 342239 | E9: 56507188 | F9: 68548437 | G9: 80000000 | H9: 17048085 | I9: 51500352 | J9: 35550997 | K9: 32997440 | L9: 200 | M9: 66.1 | N9: 21.3 | O9: 0.628 | P9: Jaipur
A10: Tamil Nadu | B10: South | C10: State | D10: 130058 | E10: 62405679 | F10: 72147030 | G10: 80000000 | H10: 34917440 | I10: 37229590 | J10: 36137975 | K10: 36009055 | L10: 555 | M10: 80.3 | N10: 15.6 | O10: 0.708 | P10: Chennai
A11: Karnataka | B11: South | C11: State | D11: 191791 | E11: 52850562 | F11: 61095297 | G11: 68000000 | H11: 23625962 | I11: 37469335 | J11: 30966657 | K11: 30128640 | L11: 319 | M11: 75.6 | N11: 15.7 | O11: 0.682 | P11: Bengaluru
A12: Gujarat | B12: West | C12: State | D12: 196024 | E12: 50671017 | F12: 60439692 | G12: 67000000 | H12: 25745083 | I12: 34694609 | J12: 31491260 | K12: 28948432 | L12: 308 | M12: 78 | N12: 19.3 | O12: 0.672 | P12: Gandhinagar
A13: Andhra Pradesh | B13: South | C13: State | D13: 162975 | E13: 76210007 | F13: 49386799 | G13: 52000000 | H13: 14738876 | I13: 34647923 | J13: 24738068 | K13: 24648731 | L13: 304 | M13: 67.4 | N13: -9 | O13: 0.649 | P13: Amaravati
A14: Telangana | B14: South | C14: State | D14: 112077 | E14: 0 | F14: 35003674 | G14: 39000000 | H14: 15694768 | I14: 19308906 | J14: 17613412 | K14: 17390262 | L14: 312 | M14: 66.5 | N14: 0 | O14: 0.659 | P14: Hyderabad
A15: Odisha | B15: East | C15: State | D15: 155707 | E15: 36804660 | F15: 41974218 | G15: 46000000 | H15: 6993745 | I15: 34980473 | J15: 21212136 | K15: 20761862 | L15: 270 | M15: 72.9 | N15: 14 | O15: 0.606 | P15: Bhubaneswar
... A39: Ladakh | B39: North | C39: UT | D39: 59146 | E39: 0 | F39: 274289 | G39: 325000 | H39: 37924 | I39: 236365 | J39: 147950 | K39: 126339 | L39: 5 | M39: 77.2 | N39: 0 | O39: 0.618 | P39: Leh
A41: * 2021 Population = Projected estimate. Census was delayed due to COVID-19.

Sheet Data_Cleaning
A1: 🔍 DATA CLEANING & QUALITY CHECKS | India Population Dataset
A2: State/UT | B2: Region | C2: Category | D2: Urban+Rural Check | E2: Gender Check | F2: Density Check | G2: Literacy Valid? | H2: Growth Rate Flag | I2: HDI Valid? | J2: Quality Status
A3: =Raw_Data!A4 -> Uttar Pradesh | B3: =Raw_Data!B4 -> North | C3: =Raw_Data!C4 -> State | D3: =IF(AND(Raw_Data!H4>0,Raw_Data!I4>0),IF(ABS((Raw_Data!H4+Raw_Data!I4)-Raw_Data!F4)<1000,"✅ Match","⚠ Mismatch"),"➖ N/A") -> ✅ Match | E3: =IF(AND(Raw_Data!J4>0,Raw_Data!K4>0),IF(ABS((Raw_Data!J4+Raw_Data!K4)-Raw_Data!F4)<5000,"✅ Match","⚠ Mismatch"),"➖ N/A") -> ✅ Match | F3: =IF(AND(Raw_Data!L4>0,Raw_Data!D4>0),IF(ABS(Raw_Data!F4/Raw_Data!D4-Raw_Data!L4)<50,"✅ OK","⚠ Check"),"➖ N/A") -> ✅ OK | G3: =IF(AND(Raw_Data!M4>=0,Raw_Data!M4<=100),"✅ Valid","❌ Out of Range") -> ✅ Valid | H3: =IF(ABS(Raw_Data!N4)>50,"⚠ Unusual",IF(Raw_Data!N4<0,"📉 Decline","✅ Normal")) -> ✅ Normal | I3: =IF(AND(Raw_Data!O4>=0,Raw_Data!O4<=1),"✅ Valid","❌ Invalid") -> ✅ Valid | J3: =IF(AND(ISNUMBER(SEARCH("✅",D3)),ISNUMBER(SEARCH("✅",G3)),ISNUMBER(SEARCH("✅",I3))),"✅ Clean","⚠ Review") -> ✅ Clean
A4: =Raw_Data!A5 -> Maharashtra | B4: =Raw_Data!B5 -> West | C4: =Raw_Data!C5 -> State | D4: =IF(AND(Raw_Data!H5>0,Raw_Data!I5>0),IF(ABS((Raw_Data!H5+Raw_Data!I5)-Raw_Data!F5)<1000,"✅ Match","⚠ Mismatch"),"➖ N/A") -> ✅ Match | E4: =IF(AND(Raw_Data!J5>0,Raw_Data!K5>0),IF(ABS((Raw_Data!J5+Raw_Data!K5)-Raw_Data!F5)<5000,"✅ Match","⚠ Mismatch"),"➖ N/A") -> ✅ Match | F4: =IF(AND(Raw_Data!L5>0,Raw_Data!D5>0),IF(ABS(Raw_Data!F5/Raw_Data!D5-Raw_Data!L5)<50,"✅ OK","⚠ Check"),"➖ N/A") -> ✅ OK | G4: =IF(AND(Raw_Data!M5>=0,Raw_Data!M5<=100),"✅ Valid","❌ Out of Range") -> ✅ Valid | H4: =IF(ABS(Raw_Data!N5)>50,"⚠ Unusual",IF(Raw_Data!N5<0,"📉 Decline","✅ Normal")) -> ✅ Normal | I4: =IF(AND(Raw_Data!O5>=0,Raw_Data!O5<=1),"✅ Valid","❌ Invalid") -> ✅ Valid | J4: =IF(AND(ISNUMBER(SEARCH("✅",D4)),ISNUMBER(SEARCH("✅",G4)),ISNUMBER(SEARCH("✅",I4))),"✅ Clean","⚠ Review") -> ✅ Clean
A5: =Raw_Data!A6 -> Bihar | B5: =Raw_Data!B6 -> East | C5: =Raw_Data!C6 -> State | D5: =IF(AND(Raw_Data!H6>0,Raw_Data!I6>0),IF(ABS((Raw_Data!H6+Raw_Data!I6)-Raw_Data!F6)<1000,"✅ Match","⚠ Mismatch"),"➖ N/A") -> ✅ Match | E5: =IF(AND(Raw_Data!J6>0,Raw_Data!K6>0),IF(ABS((Raw_Data!J6+Raw_Data!K6)-Raw_Data!F6)<5000,"✅ Match","⚠ Mismatch"),"➖ N/A") -> ✅ Match | F5: =IF(AND(Raw_Data!L6>0,Raw_Data!D6>0),IF(ABS(Raw_Data!F6/Raw_Data!D6-Raw_Data!L6)<50,"✅ OK","⚠ Check"),"➖ N/A") -> ✅ OK | G5: =IF(AND(Raw_Data!M6>=0,Raw_Data!M6<=100),"✅ Valid","❌ Out of Range") -> ✅ Valid | H5: =IF(ABS(Raw_Data!N6)>50,"⚠ Unusual",IF(Raw_Data!N6<0,"📉 Decline","✅ Normal")) -> ✅ Normal | I5: =IF(AND(Raw_Data!O6>=0,Raw_Data!O6<=1),"✅ Valid","❌ Invalid") -> ✅ Valid | J5: =IF(AND(ISNUMBER(SEARCH("✅",D5)),ISNUMBER(SEARCH("✅",G5)),ISNUMBER(SEARCH("✅",I5))),"✅ Clean","⚠ Review") -> ✅ Clean
A6: =Raw_Data!A7 -> West Bengal | B6: =Raw_Data!B7 -> East | C6: =Raw_Data!C7 -> State | D6: =IF(AND(Raw_Data!H7>0,Raw_Data!I7>0),IF(ABS((Raw_Data!H7+Raw_Data!I7)-Raw_Data!F7)<1000,"✅ Match","⚠ Mismatch"),"➖ N/A") -> ✅ Match | E6: =IF(AND(Raw_Data!J7>0,Raw_Data!K7>0),IF(ABS((Raw_Data!J7+Raw_Data!K7)-Raw_Data!F7)<5000,"✅ Match","⚠ Mismatch"),"➖ N/A") -> ✅ Match | F6: =IF(AND(Raw_Data!L7>0,Raw_Data!D7>0),IF(ABS(Raw_Data!F7/Raw_Data!D7-Raw_Data!L7)<50,"✅ OK","⚠ Check"),"➖ N/A") -> ✅ OK | G6: =IF(AND(Raw_Data!M7>=0,Raw_Data!M7<=100),"✅ Valid","❌ Out of Range") -> ✅ Valid | H6: =IF(ABS(Raw_Data!N7)>50,"⚠ Unusual",IF(Raw_Data!N7<0,"📉 Decline","✅ Normal")) -> ✅ Normal | I6: =IF(AND(Raw_Data!O7>=0,Raw_Data!O7<=1),"✅ Valid","❌ Invalid") -> ✅ Valid | J6: =IF(AND(ISNUMBER(SEARCH("✅",D6)),ISNUMBER(SEARCH("✅",G6)),ISNUMBER(SEARCH("✅",I6))),"✅ Clean","⚠ Review") -> ✅ Clean
A7: =Raw_Data!A8 -> Madhya Pradesh | B7: =Raw_Data!B8 -> Central | C7: =Raw_Data!C8 -> State | D7: =IF(AND(Raw_Data!H8>0,Raw_Data!I8>0),IF(ABS((Raw_Data!H8+Raw_Data!I8)-Raw_Data!F8)<1000,"✅ Match","⚠ Mismatch"),"➖ N/A") -> ✅ Match | E7: =IF(AND(Raw_Data!J8>0,Raw_Data!K8>0),IF(ABS((Raw_Data!J8+Raw_Data!K8)-Raw_Data!F8)<5000,"✅ Match","⚠ Mismatch"),"➖ N/A") -> ✅ Match | F7: =IF(AND(Raw_Data!L8>0,Raw_Data!D8>0),IF(ABS(Raw_Data!F8/Raw_Data!D8-Raw_Data!L8)<50,"✅ OK","⚠ Check"),"➖ N/A") -> ✅ OK | G7: =IF(AND(Raw_Data!M8>=0,Raw_Data!M8<=100),"✅ Valid","❌ Out of Range") -> ✅ Valid | H7: =IF(ABS(Raw_Data!N8)>50,"⚠ Unusual",IF(Raw_Data!N8<0,"📉 Decline","✅ Normal")) -> ✅ Normal | I7: =IF(AND(Raw_Data!O8>=0,Raw_Data!O8<=1),"✅ Valid","❌ Invalid") -> ✅ Valid | J7: =IF(AND(ISNUMBER(SEARCH("✅",D7)),ISNUMBER(SEARCH("✅",G7)),ISNUMBER(SEARCH("✅",I7))),"✅ Clean","⚠ Review") -> ✅ Clean
A8: =Raw_Data!A9 -> Rajasthan | B8: =Raw_Data!B9 -> North | C8: =Raw_Data!C9 -> State | D8: =IF(AND(Raw_Data!H9>0,Raw_Data!I9>0),IF(ABS((Raw_Data!H9+Raw_Data!I9)-Raw_Data!F9)<1000,"✅ Match","⚠ Mismatch"),"➖ N/A") -> ✅ Match | E8: =IF(AND(Raw_Data!J9>0,Raw_Data!K9>0),IF(ABS((Raw_Data!J9+Raw_Data!K9)-Raw_Data!F9)<5000,"✅ Match","⚠ Mismatch"),"➖ N/A") -> ✅ Match | F8: =IF(AND(Raw_Data!L9>0,Raw_Data!D9>0),IF(ABS(Raw_Data!F9/Raw_Data!D9-Raw_Data!L9)<50,"✅ OK","⚠ Check"),"➖ N/A") -> ✅ OK | G8: =IF(AND(Raw_Data!M9>=0,Raw_Data!M9<=100),"✅ Valid","❌ Out of Range") -> ✅ Valid | H8: =IF(ABS(Raw_Data!N9)>50,"⚠ Unusual",IF(Raw_Data!N9<0,"📉 Decline","✅ Normal")) -> ✅ Normal | I8: =IF(AND(Raw_Data!O9>=0,Raw_Data!O9<=1),"✅ Valid","❌ Invalid") -> ✅ Valid | J8: =IF(AND(ISNUMBER(SEARCH("✅",D8)),ISNUMBER(SEARCH("✅",G8)),ISNUMBER(SEARCH("✅",I8))),"✅ Clean","⚠ Review") -> ✅ Clean
A9: =Raw_Data!A10 -> Tamil Nadu | B9: =Raw_Data!B10 -> South | C9: =Raw_Data!C10 -> State | D9: =IF(AND(Raw_Data!H10>0,Raw_Data!I10>0),IF(ABS((Raw_Data!H10+Raw_Data!I10)-Raw_Data!F10)<1000,"✅ Match","⚠ Mismatch"),"➖ N/A") -> ✅ Match | E9: =IF(AND(Raw_Data!J10>0,Raw_Data!K10>0),IF(ABS((Raw_Data!J10+Raw_Data!K10)-Raw_Data!F10)<5000,"✅ Match","⚠ Mismatch"),"➖ N/A") -> ✅ Match | F9: =IF(AND(Raw_Data!L10>0,Raw_Data!D10>0),IF(ABS(Raw_Data!F10/Raw_Data!D10-Raw_Data!L10)<50,"✅ OK","⚠ Check"),"➖ N/A") -> ✅ OK | G9: =IF(AND(Raw_Data!M10>=0,Raw_Data!M10<=100),"✅ Valid","❌ Out of Range") -> ✅ Valid | H9: =IF(ABS(Raw_Data!N10)>50,"⚠ Unusual",IF(Raw_Data!N10<0,"📉 Decline","✅ Normal")) -> ✅ Normal | I9: =IF(AND(Raw_Data!O10>=0,Raw_Data!O10<=1),"✅ Valid","❌ Invalid") -> ✅ Valid | J9: =IF(AND(ISNUMBER(SEARCH("✅",D9)),ISNUMBER(SEARCH("✅",G9)),ISNUMBER(SEARCH("✅",I9))),"✅ Clean","⚠ Review") -> ✅ Clean
A10: =Raw_Data!A11 -> Karnataka | B10: =Raw_Data!B11 -> South | C10: =Raw_Data!C11 -> State | D10: =IF(AND(Raw_Data!H11>0,Raw_Data!I11>0),IF(ABS((Raw_Data!H11+Raw_Data!I11)-Raw_Data!F11)<1000,"✅ Match","⚠ Mismatch"),"➖ N/A") -> ✅ Match | E10: =IF(AND(Raw_Data!J11>0,Raw_Data!K11>0),IF(ABS((Raw_Data!J11+Raw_Data!K11)-Raw_Data!F11)<5000,"✅ Match","⚠ Mismatch"),"➖ N/A") -> ✅ Match | F10: =IF(AND(Raw_Data!L11>0,Raw_Data!D11>0),IF(ABS(Raw_Data!F11/Raw_Data!D11-Raw_Data!L11)<50,"✅ OK","⚠ Check"),"➖ N/A") -> ✅ OK | G10: =IF(AND(Raw_Data!M11>=0,Raw_Data!M11<=100),"✅ Valid","❌ Out of Range") -> ✅ Valid | H10: =IF(ABS(Raw_Data!N11)>50,"⚠ Unusual",IF(Raw_Data!N11<0,"📉 Decline","✅ Normal")) -> ✅ Normal | I10: =IF(AND(Raw_Data!O11>=0,Raw_Data!O11<=1),"✅ Valid","❌ Invalid") -> ✅ Valid | J10: =IF(AND(ISNUMBER(SEARCH("✅",D10)),ISNUMBER(SEARCH("✅",G10)),ISNUMBER(SEARCH("✅",I10))),"✅ Clean","⚠ Review") -> ✅ Clean
A11: =Raw_Data!A12 -> Gujarat | B11: =Raw_Data!B12 -> West | C11: =Raw_Data!C12 -> State | D11: =IF(AND(Raw_Data!H12>0,Raw_Data!I12>0),IF(ABS((Raw_Data!H12+Raw_Data!I12)-Raw_Data!F12)<1000,"✅ Match","⚠ Mismatch"),"➖ N/A") -> ✅ Match | E11: =IF(AND(Raw_Data!J12>0,Raw_Data!K12>0),IF(ABS((Raw_Data!J12+Raw_Data!K12)-Raw_Data!F12)<5000,"✅ Match","⚠ Mismatch"),"➖ N/A") -> ✅ Match | F11: =IF(AND(Raw_Data!L12>0,Raw_Data!D12>0),IF(ABS(Raw_Data!F12/Raw_Data!D12-Raw_Data!L12)<50,"✅ OK","⚠ Check"),"➖ N/A") -> ✅ OK | G11: =IF(AND(Raw_Data!M12>=0,Raw_Data!M12<=100),"✅ Valid","❌ Out of Range") -> ✅ Valid | H11: =IF(ABS(Raw_Data!N12)>50,"⚠ Unusual",IF(Raw_Data!N12<0,"📉 Decline","✅ Normal")) -> ✅ Normal | I11: =IF(AND(Raw_Data!O12>=0,Raw_Data!O12<=1),"✅ Valid","❌ Invalid") -> ✅ Valid | J11: =IF(AND(ISNUMBER(SEARCH("✅",D11)),ISNUMBER(SEARCH("✅",G11)),ISNUMBER(SEARCH("✅",I11))),"✅ Clean","⚠ Review") -> ✅ Clean
A12: =Raw_Data!A13 -> Andhra Pradesh | B12: =Raw_Data!B13 -> South | C12: =Raw_Data!C13 -> State | D12: =IF(AND(Raw_Data!H13>0,Raw_Data!I13>0),IF(ABS((Raw_Data!H13+Raw_Data!I13)-Raw_Data!F13)<1000,"✅ Match","⚠ Mismatch"),"➖ N/A") -> ✅ Match | E12: =IF(AND(Raw_Data!J13>0,Raw_Data!K13>0),IF(ABS((Raw_Data!J13+Raw_Data!K13)-Raw_Data!F13)<5000,"✅ Match","⚠ Mismatch"),"➖ N/A") -> ✅ Match | F12: =IF(AND(Raw_Data!L13>0,Raw_Data!D13>0),IF(ABS(Raw_Data!F13/Raw_Data!D13-Raw_Data!L13)<50,"✅ OK","⚠ Check"),"➖ N/A") -> ✅ OK | G12: =IF(AND(Raw_Data!M13>=0,Raw_Data!M13<=100),"✅ Valid","❌ Out of Range") -> ✅ Valid | H12: =IF(ABS(Raw_Data!N13)>50,"⚠ Unusual",IF(Raw_Data!N13<0,"📉 Decline","✅ Normal")) -> 📉 Decline | I12: =IF(AND(Raw_Data!O13>=0,Raw_Data!O13<=1),"✅ Valid","❌ Invalid") -> ✅ Valid | J12: =IF(AND(ISNUMBER(SEARCH("✅",D12)),ISNUMBER(SEARCH("✅",G12)),ISNUMBER(SEARCH("✅",I12))),"✅ Clean","⚠ Review") -> ✅ Clean
A13: =Raw_Data!A14 -> Telangana | B13: =Raw_Data!B14 -> South | C13: =Raw_Data!C14 -> State | D13: =IF(AND(Raw_Data!H14>0,Raw_Data!I14>0),IF(ABS((Raw_Data!H14+Raw_Data!I14)-Raw_Data!F14)<1000,"✅ Match","⚠ Mismatch"),"➖ N/A") -> ✅ Match | E13: =IF(AND(Raw_Data!J14>0,Raw_Data!K14>0),IF(ABS((Raw_Data!J14+Raw_Data!K14)-Raw_Data!F14)<5000,"✅ Match","⚠ Mismatch"),"➖ N/A") -> ✅ Match | F13: =IF(AND(Raw_Data!L14>0,Raw_Data!D14>0),IF(ABS(Raw_Data!F14/Raw_Data!D14-Raw_Data!L14)<50,"✅ OK","⚠ Check"),"➖ N/A") -> ✅ OK | G13: =IF(AND(Raw_Data!M14>=0,Raw_Data!M14<=100),"✅ Valid","❌ Out of Range") -> ✅ Valid | H13: =IF(ABS(Raw_Data!N14)>50,"⚠ Unusual",IF(Raw_Data!N14<0,"📉 Decline","✅ Normal")) -> ✅ Normal | I13: =IF(AND(Raw_Data!O14>=0,Raw_Data!O14<=1),"✅ Valid","❌ Invalid") -> ✅ Valid | J13: =IF(AND(ISNUMBER(SEARCH("✅",D13)),ISNUMBER(SEARCH("✅",G13)),ISNUMBER(SEARCH("✅",I13))),"✅ Clean","⚠ Review") -> ✅ Clean
A14: =Raw_Data!A15 -> Odisha | B14: =Raw_Data!B15 -> East | C14: =Raw_Data!C15 -> State | D14: =IF(AND(Raw_Data!H15>0,Raw_Data!I15>0),IF(ABS((Raw_Data!H15+Raw_Data!I15)-Raw_Data!F15)<1000,"✅ Match","⚠ Mismatch"),"➖ N/A") -> ✅ Match | E14: =IF(AND(Raw_Data!J15>0,Raw_Data!K15>0),IF(ABS((Raw_Data!J15+Raw_Data!K15)-Raw_Data!F15)<5000,"✅ Match","⚠ Mismatch"),"➖ N/A") -> ✅ Match | F14: =IF(AND(Raw_Data!L15>0,Raw_Data!D15>0),IF(ABS(Raw_Data!F15/Raw_Data!D15-Raw_Data!L15)<50,"✅ OK","⚠ Check"),"➖ N/A") -> ✅ OK | G14: =IF(AND(Raw_Data!M15>=0,Raw_Data!M15<=100),"✅ Valid","❌ Out of Range") -> ✅ Valid | H14: =IF(ABS(Raw_Data!N15)>50,"⚠ Unusual",IF(Raw_Data!N15<0,"📉 Decline","✅ Normal")) -> ✅ Normal | I14: =IF(AND(Raw_Data!O15>=0,Raw_Data!O15<=1),"✅ Valid","❌ Invalid") -> ✅ Valid | J14: =IF(AND(ISNUMBER(SEARCH("✅",D14)),ISNUMBER(SEARCH("✅",G14)),ISNUMBER(SEARCH("✅",I14))),"✅ Clean","⚠ Review") -> ✅ Clean
... A38: =Raw_Data!A39 -> Ladakh | B38: =Raw_Data!B39 -> North | C38: =Raw_Data!C39 -> UT | D38: =IF(AND(Raw_Data!H39>0,Raw_Data!I39>0),IF(ABS((Raw_Data!H39+Raw_Data!I39)-Raw_Data!F39)<1000,"✅ Match","⚠ Mismatch"),"➖ N/A") -> ✅ Match | E38: =IF(AND(Raw_Data!J39>0,Raw_Data!K39>0),IF(ABS((Raw_Data!J39+Raw_Data!K39)-Raw_Data!F39)<5000,"✅ Match","⚠ Mismatch"),"➖ N/A") -> ✅ Match | F38: =IF(AND(Raw_Data!L39>0,Raw_Data!D39>0),IF(ABS(Raw_Data!F39/Raw_Data!D39-Raw_Data!L39)<50,"✅ OK","⚠ Check"),"➖ N/A") -> ✅ OK | G38: =IF(AND(Raw_Data!M39>=0,Raw_Data!M39<=100),"✅ Valid","❌ Out of Range") -> ✅ Valid | H38: =IF(ABS(Raw_Data!N39)>50,"⚠ Unusual",IF(Raw_Data!N39<0,"📉 Decline","✅ Normal")) -> ✅ Normal | I38: =IF(AND(Raw_Data!O39>=0,Raw_Data!O39<=1),"✅ Valid","❌ Invalid") -> ✅ Valid | J38: =IF(AND(ISNUMBER(SEARCH("✅",D38)),ISNUMBER(SEARCH("✅",G38)),ISNUMBER(SEARCH("✅",I38))),"✅ Clean","⚠ Review") -> ✅ Clean

Sheet Analysis
A1: 📊 POPULATION ANALYSIS | India State-wise Metrics & Formulas
A3: SECTION A — State-wise Summary (SUMIF / AVERAGEIF / COUNTIF / VLOOKUP)
A4: State/UT | B4: Region | C4: Category | D4: Population 2011 | E4: Population 2021* | F4: Pop Growth (Abs) | G4: Growth % | H4: Density 2011 | I4: Literacy %
A5: Uttar Pradesh | B5: =VLOOKUP(A5,Raw_Data!A:B,2,FALSE()) -> North | C5: =VLOOKUP(A5,Raw_Data!A:C,3,FALSE()) -> State | D5: =IFERROR(VLOOKUP(A5,Raw_Data!A:F,6,FALSE()),0) -> 199812341 | E5: =IFERROR(VLOOKUP(A5,Raw_Data!A:G,7,FALSE()),0) -> 235000000 | F5: =IF(AND(D5>0,E5>0),E5-D5,"") -> 35187659 | G5: =IF(D5>0,F5/D5,"") -> 0.17610353 | H5: =IFERROR(VLOOKUP(A5,Raw_Data!A:L,12,FALSE()),"") -> 829 | I5: =IFERROR(VLOOKUP(A5,Raw_Data!A:M,13,FALSE()),"") -> 67.7
A6: Maharashtra | B6: =VLOOKUP(A6,Raw_Data!A:B,2,FALSE()) -> West | C6: =VLOOKUP(A6,Raw_Data!A:C,3,FALSE()) -> State | D6: =IFERROR(VLOOKUP(A6,Raw_Data!A:F,6,FALSE()),0) -> 112374333 | E6: =IFERROR(VLOOKUP(A6,Raw_Data!A:G,7,FALSE()),0) -> 126000000 | F6: =IF(AND(D6>0,E6>0),E6-D6,"") -> 13625667 | G6: =IF(D6>0,F6/D6,"") -> 0.12125248 | H6: =IFERROR(VLOOKUP(A6,Raw_Data!A:L,12,FALSE()),"") -> 365 | I6: =IFERROR(VLOOKUP(A6,Raw_Data!A:M,13,FALSE()),"") -> 82.9
A7: Bihar | B7: =VLOOKUP(A7,Raw_Data!A:B,2,FALSE()) -> East | C7: =VLOOKUP(A7,Raw_Data!A:C,3,FALSE()) -> State | D7: =IFERROR(VLOOKUP(A7,Raw_Data!A:F,6,FALSE()),0) -> 104099452 | E7: =IFERROR(VLOOKUP(A7,Raw_Data!A:G,7,FALSE()),0) -> 121000000 | F7: =IF(AND(D7>0,E7>0),E7-D7,"") -> 16900548 | G7: =IF(D7>0,F7/D7,"") -> 0.16235002 | H7: =IFERROR(VLOOKUP(A7,Raw_Data!A:L,12,FALSE()),"") -> 1106 | I7: =IFERROR(VLOOKUP(A7,Raw_Data!A:M,13,FALSE()),"") -> 63.8
A8: West Bengal | B8: =VLOOKUP(A8,Raw_Data!A:B,2,FALSE()) -> East | C8: =VLOOKUP(A8,Raw_Data!A:C,3,FALSE()) -> State | D8: =IFERROR(VLOOKUP(A8,Raw_Data!A:F,6,FALSE()),0) -> 91276115 | E8: =IFERROR(VLOOKUP(A8,Raw_Data!A:G,7,FALSE()),0) -> 100000000 | F8: =IF(AND(D8>0,E8>0),E8-D8,"") -> 8723885 | G8: =IF(D8>0,F8/D8,"") -> 0.095576866 | H8: =IFERROR(VLOOKUP(A8,Raw_Data!A:L,12,FALSE()),"") -> 1028 | I8: =IFERROR(VLOOKUP(A8,Raw_Data!A:M,13,FALSE()),"") -> 77.1
A9: Madhya Pradesh | B9: =VLOOKUP(A9,Raw_Data!A:B,2,FALSE()) -> Central | C9: =VLOOKUP(A9,Raw_Data!A:C,3,FALSE()) -> State | D9: =IFERROR(VLOOKUP(A9,Raw_Data!A:F,6,FALSE()),0) -> 72626809 | E9: =IFERROR(VLOOKUP(A9,Raw_Data!A:G,7,FALSE()),0) -> 84000000 | F9: =IF(AND(D9>0,E9>0),E9-D9,"") -> 11373191 | G9: =IF(D9>0,F9/D9,"") -> 0.1565977 | H9: =IFERROR(VLOOKUP(A9,Raw_Data!A:L,12,FALSE()),"") -> 236 | I9: =IFERROR(VLOOKUP(A9,Raw_Data!A:M,13,FALSE()),"") -> 70.6
A10: Rajasthan | B10: =VLOOKUP(A10,Raw_Data!A:B,2,FALSE()) -> North | C10: =VLOOKUP(A10,Raw_Data!A:C,3,FALSE()) -> State | D10: =IFERROR(VLOOKUP(A10,Raw_Data!A:F,6,FALSE()),0) -> 68548437 | E10: =IFERROR(VLOOKUP(A10,Raw_Data!A:G,7,FALSE()),0) -> 80000000 | F10: =IF(AND(D10>0,E10>0),E10-D10,"") -> 11451563 | G10: =IF(D10>0,F10/D10,"") -> 0.16705797 | H10: =IFERROR(VLOOKUP(A10,Raw_Data!A:L,12,FALSE()),"") -> 200 | I10: =IFERROR(VLOOKUP(A10,Raw_Data!A:M,13,FALSE()),"") -> 66.1
A11: Tamil Nadu | B11: =VLOOKUP(A11,Raw_Data!A:B,2,FALSE()) -> South | C11: =VLOOKUP(A11,Raw_Data!A:C,3,FALSE()) -> State | D11: =IFERROR(VLOOKUP(A11,Raw_Data!A:F,6,FALSE()),0) -> 72147030 | E11: =IFERROR(VLOOKUP(A11,Raw_Data!A:G,7,FALSE()),0) -> 80000000 | F11: =IF(AND(D11>0,E11>0),E11-D11,"") -> 7852970 | G11: =IF(D11>0,F11/D11,"") -> 0.10884675 | H11: =IFERROR(VLOOKUP(A11,Raw_Data!A:L,12,FALSE()),"") -> 555 | I11: =IFERROR(VLOOKUP(A11,Raw_Data!A:M,13,FALSE()),"") -> 80.3
A12: Karnataka | B12: =VLOOKUP(A12,Raw_Data!A:B,2,FALSE()) -> South | C12: =VLOOKUP(A12,Raw_Data!A:C,3,FALSE()) -> State | D12: =IFERROR(VLOOKUP(A12,Raw_Data!A:F,6,FALSE()),0) -> 61095297 | E12: =IFERROR(VLOOKUP(A12,Raw_Data!A:G,7,FALSE()),0) -> 68000000 | F12: =IF(AND(D12>0,E12>0),E12-D12,"") -> 6904703 | G12: =IF(D12>0,F12/D12,"") -> 0.11301529 | H12: =IFERROR(VLOOKUP(A12,Raw_Data!A:L,12,FALSE()),"") -> 319 | I12: =IFERROR(VLOOKUP(A12,Raw_Data!A:M,13,FALSE()),"") -> 75.6
A13: Gujarat | B13: =VLOOKUP(A13,Raw_Data!A:B,2,FALSE()) -> West | C13: =VLOOKUP(A13,Raw_Data!A:C,3,FALSE()) -> State | D13: =IFERROR(VLOOKUP(A13,Raw_Data!A:F,6,FALSE()),0) -> 60439692 | E13: =IFERROR(VLOOKUP(A13,Raw_Data!A:G,7,FALSE()),0) -> 67000000 | F13: =IF(AND(D13>0,E13>0),E13-D13,"") -> 6560308 | G13: =IF(D13>0,F13/D13,"") -> 0.10854304 | H13: =IFERROR(VLOOKUP(A13,Raw_Data!A:L,12,FALSE()),"") -> 308 | I13: =IFERROR(VLOOKUP(A13,Raw_Data!A:M,13,FALSE()),"") -> 78
A14: Andhra Pradesh | B14: =VLOOKUP(A14,Raw_Data!A:B,2,FALSE()) -> South | C14: =VLOOKUP(A14,Raw_Data!A:C,3,FALSE()) -> State | D14: =IFERROR(VLOOKUP(A14,Raw_Data!A:F,6,FALSE()),0) -> 49386799 | E14: =IFERROR(VLOOKUP(A14,Raw_Data!A:G,7,FALSE()),0) -> 52000000 | F14: =IF(AND(D14>0,E14>0),E14-D14,"") -> 2613201 | G14: =IF(D14>0,F14/D14,"") -> 0.052912945 | H14: =IFERROR(VLOOKUP(A14,Raw_Data!A:L,12,FALSE()),"") -> 304 | I14: =IFERROR(VLOOKUP(A14,Raw_Data!A:M,13,FALSE()),"") -> 67.4
A15: Telangana | B15: =VLOOKUP(A15,Raw_Data!A:B,2,FALSE()) -> South | C15: =VLOOKUP(A15,Raw_Data!A:C,3,FALSE()) -> State | D15: =IFERROR(VLOOKUP(A15,Raw_Data!A:F,6,FALSE()),0) -> 35003674 | E15: =IFERROR(VLOOKUP(A15,Raw_Data!A:G,7,FALSE()),0) -> 39000000 | F15: =IF(AND(D15>0,E15>0),E15-D15,"") -> 3996326 | G15: =IF(D15>0,F15/D15,"") -> 0.11416876 | H15: =IFERROR(VLOOKUP(A15,Raw_Data!A:L,12,FALSE()),"") -> 312 | I15: =IFERROR(VLOOKUP(A15,Raw_Data!A:M,13,FALSE()),"") -> 66.5
A16: Odisha | B16: =VLOOKUP(A16,Raw_Data!A:B,2,FALSE()) -> East | C16: =VLOOKUP(A16,Raw_Data!A:C,3,FALSE()) -> State | D16: =IFERROR(VLOOKUP(A16,Raw_Data!A:F,6,FALSE()),0) -> 41974218 | E16: =IFERROR(VLOOKUP(A16,Raw_Data!A:G,7,FALSE()),0) -> 46000000 | F16: =IF(AND(D16>0,E16>0),E16-D16,"") -> 4025782 | G16: =IF(D16>0,F16/D16,"") -> 0.095910828 | H16: =IFERROR(VLOOKUP(A16,Raw_Data!A:L,12,FALSE()),"") -> 270 | I16: =IFERROR(VLOOKUP(A16,Raw_Data!A:M,13,FALSE()),"") -> 72.9
... A40: Ladakh | B40: =VLOOKUP(A40,Raw_Data!A:B,2,FALSE()) -> North | C40: =VLOOKUP(A40,Raw_Data!A:C,3,FALSE()) -> UT | D40: =IFERROR(VLOOKUP(A40,Raw_Data!A:F,6,FALSE()),0) -> 274289 | E40: =IFERROR(VLOOKUP(A40,Raw_Data!A:G,7,FALSE()),0) -> 325000 | F40: =IF(AND(D40>0,E40>0),E40-D40,"") -> 50711 | G40: =IF(D40>0,F40/D40,"") -> 0.18488164 | H40: =IFERROR(VLOOKUP(A40,Raw_Data!A:L,12,FALSE()),"") -> 5 | I40: =IFERROR(VLOOKUP(A40,Raw_Data!A:M,13,FALSE()),"") -> 77.2
A41: INDIA TOTALS
A42: INDIA TOTAL | D42: =SUM(D5:D40) -> 1210938962 | E42: =SUM(E5:E40) -> 1367115000 | F42: =E42-D42 -> 156176038 | G42: =IF(D42>0,F42/D42,"") -> 0.12897102 | H42: =AVERAGEIF(Raw_Data!C:C,"State",Raw_Data!L:L) -> 371.67857 | I42: =AVERAGEIF(Raw_Data!A:A,"<>",Raw_Data!M:M) -> 77.85
A44: SECTION B — Regional Analysis (SUMIFS / AVERAGEIFS / COUNTIFS)
A45: Region | B45: States Count | C45: Total Pop 2011 | D45: Total Pop 2021 | E45: Urban Pop | F45: Rural Pop | G45: Avg Literacy | H45: Avg Density
A46: North | B46: =COUNTIF(Raw_Data!B:B,A46) -> 10 | C46: =SUMIF(Raw_Data!B:B,A46,Raw_Data!F:F) -> 369065454 | D46: =SUMIF(Raw_Data!B:B,A46,Raw_Data!G:G) -> 427525000 | E46: =SUMIF(Raw_Data!B:B,A46,Raw_Data!H:H) -> 105348700 | F46: =SUMIF(Raw_Data!B:B,A46,Raw_Data!I:I) -> 263716754 | G46: =AVERAGEIF(Raw_Data!B:B,A46,Raw_Data!M:M) -> 76.91 | H46: =AVERAGEIF(Raw_Data!B:B,A46,Raw_Data!L:L) -> 2334.5
A47: South | B47: =COUNTIF(Raw_Data!B:B,A47) -> 7 | C47: =SUMIF(Raw_Data!B:B,A47,Raw_Data!F:F) -> 252351287 | D47: =SUMIF(Raw_Data!B:B,A47,Raw_Data!G:G) -> 275470000 | E47: =SUMIF(Raw_Data!B:B,A47,Raw_Data!H:H) -> 105809672 | F47: =SUMIF(Raw_Data!B:B,A47,Raw_Data!I:I) -> 146541615 | G47: =AVERAGEIF(Raw_Data!B:B,A47,Raw_Data!M:M) -> 80.385714 | H47: =AVERAGEIF(Raw_Data!B:B,A47,Raw_Data!L:L) -> 994.42857
A48: East | B48: =COUNTIF(Raw_Data!B:B,A48) -> 5 | C48: =SUMIF(Raw_Data!B:B,A48,Raw_Data!F:F) -> 270718500 | D48: =SUMIF(Raw_Data!B:B,A48,Raw_Data!G:G) -> 304420000 | E48: =SUMIF(Raw_Data!B:B,A48,Raw_Data!H:H) -> 55959909 | F48: =SUMIF(Raw_Data!B:B,A48,Raw_Data!I:I) -> 214758591 | G48: =AVERAGEIF(Raw_Data!B:B,A48,Raw_Data!M:M) -> 73.54 | H48: =AVERAGEIF(Raw_Data!B:B,A48,Raw_Data!L:L) -> 572.8
A49: West | B49: =COUNTIF(Raw_Data!B:B,A49) -> 4 | C49: =SUMIF(Raw_Data!B:B,A49,Raw_Data!F:F) -> 174859526 | D49: =SUMIF(Raw_Data!B:B,A49,Raw_Data!G:G) -> 195350000 | E49: =SUMIF(Raw_Data!B:B,A49,Raw_Data!H:H) -> 77643413 | F49: =SUMIF(Raw_Data!B:B,A49,Raw_Data!I:I) -> 97216113 | G49: =AVERAGEIF(Raw_Data!B:B,A49,Raw_Data!M:M) -> 81.825 | H49: =AVERAGEIF(Raw_Data!B:B,A49,Raw_Data!L:L) -> 441.25
A50: Central | B50: =COUNTIF(Raw_Data!B:B,A50) -> 2 | C50: =SUMIF(Raw_Data!B:B,A50,Raw_Data!F:F) -> 98172007 | D50: =SUMIF(Raw_Data!B:B,A50,Raw_Data!G:G) -> 113000000 | E50: =SUMIF(Raw_Data!B:B,A50,Raw_Data!H:H) -> 25998028 | F50: =SUMIF(Raw_Data!B:B,A50,Raw_Data!I:I) -> 72173979 | G50: =AVERAGEIF(Raw_Data!B:B,A50,Raw_Data!M:M) -> 70.8 | H50: =AVERAGEIF(Raw_Data!B:B,A50,Raw_Data!L:L) -> 212.5
A51: Northeast | B51: =COUNTIF(Raw_Data!B:B,A51) -> 8 | C51: =SUMIF(Raw_Data!B:B,A51,Raw_Data!F:F) -> 45772188 | D51: =SUMIF(Raw_Data!B:B,A51,Raw_Data!G:G) -> 51350000 | E51: =SUMIF(Raw_Data!B:B,A51,Raw_Data!H:H) -> 8382177 | F51: =SUMIF(Raw_Data!B:B,A51,Raw_Data!I:I) -> 37390011 | G51: =AVERAGEIF(Raw_Data!B:B,A51,Raw_Data!M:M) -> 79.275 | H51: =AVERAGEIF(Raw_Data!B:B,A51,Raw_Data!L:L) -> 160.25
A55: SECTION C — Urban vs Rural Summary (SUMIFS / IF / COUNTIFS)
A56: Category | B56: States | C56: Total Pop 2011 | D56: Urban Pop | E56: Rural Pop | F56: Urban % | G56: Rural %
A57: States Only | B57: =COUNTIF(Raw_Data!C:C,"State") -> 28 | C57: =SUMIF(Raw_Data!C:C,"State",Raw_Data!F:F) -> 1178000017 | D57: =SUMIF(Raw_Data!C:C,"State",Raw_Data!H:H) -> 357057299 | E57: =SUMIF(Raw_Data!C:C,"State",Raw_Data!I:I) -> 820942718 | F57: =IF(C57>0,D57/C57,0) -> 0.30310466 | G57: =IF(C57>0,E57/C57,0) -> 0.69689534
A58: UTs Only | B58: =COUNTIF(Raw_Data!C:C,"UT") -> 8 | C58: =SUMIF(Raw_Data!C:C,"UT",Raw_Data!F:F) -> 32938945 | D58: =SUMIF(Raw_Data!C:C,"UT",Raw_Data!H:H) -> 22084600 | E58: =SUMIF(Raw_Data!C:C,"UT",Raw_Data!I:I) -> 10854345 | F58: =IF(C58>0,D58/C58,0) -> 0.67047078 | G58: =IF(C58>0,E58/C58,0) -> 0.32952922
A59: All India | B59: =COUNTA(Raw_Data!A4:A39) -> 36 | C59: =SUM(Raw_Data!F4:F39) -> 1210938962 | D59: =SUM(Raw_Data!H4:H39) -> 379141899 | E59: =SUM(Raw_Data!I4:I39) -> 831797063 | F59: =IF(C59>0,D59/C59,0) -> 0.31309745 | G59: =IF(C59>0,E59/C59,0) -> 0.68690255
A63: SECTION D — Rankings & Extremes (LARGE / SMALL / IF / RANK)
A64: Metric | B64: #1 | C64: #2 | D64: #3 | E64: #4 | F64: #5
A65: Most Populous (2021) | B65: =INDEX(Raw_Data!$A$4:$A$39,MATCH(LARGE(Raw_Data!$G$4:$G$39,1),Raw_Data!$G$4:$G$39,0)) -> Uttar Pradesh | C65: =INDEX(Raw_Data!$A$4:$A$39,MATCH(LARGE(Raw_Data!$G$4:$G$39,2),Raw_Data!$G$4:$G$39,0)) -> Maharashtra | D65: =INDEX(Raw_Data!$A$4:$A$39,MATCH(LARGE(Raw_Data!$G$4:$G$39,3),Raw_Data!$G$4:$G$39,0)) -> Bihar | E65: =INDEX(Raw_Data!$A$4:$A$39,MATCH(LARGE(Raw_Data!$G$4:$G$39,4),Raw_Data!$G$4:$G$39,0)) -> West Bengal | F65: =INDEX(Raw_Data!$A$4:$A$39,MATCH(LARGE(Raw_Data!$G$4:$G$39,5),Raw_Data!$G$4:$G$39,0)) -> Madhya Pradesh
A66: Highest Density | B66: =INDEX(Raw_Data!$A$4:$A$39,MATCH(LARGE(Raw_Data!$L$4:$L$39,1),Raw_Data!$L$4:$L$39,0)) -> Delhi | C66: =INDEX(Raw_Data!$A$4:$A$39,MATCH(LARGE(Raw_Data!$L$4:$L$39,2),Raw_Data!$L$4:$L$39,0)) -> Chandigarh | D66: =INDEX(Raw_Data!$A$4:$A$39,MATCH(LARGE(Raw_Data!$L$4:$L$39,3),Raw_Data!$L$4:$L$39,0)) -> Puducherry | E66: =INDEX(Raw_Data!$A$4:$A$39,MATCH(LARGE(Raw_Data!$L$4:$L$39,4),Raw_Data!$L$4:$L$39,0)) -> Lakshadweep | F66: =INDEX(Raw_Data!$A$4:$A$39,MATCH(LARGE(Raw_Data!$L$4:$L$39,5),Raw_Data!$L$4:$L$39,0)) -> Bihar
A67: Best Literacy | B67: =INDEX(Raw_Data!$A$4:$A$39,MATCH(LARGE(Raw_Data!$M$4:$M$39,1),Raw_Data!$M$4:$M$39,0)) -> Kerala | C67: =INDEX(Raw_Data!$A$4:$A$39,MATCH(LARGE(Raw_Data!$M$4:$M$39,2),Raw_Data!$M$4:$M$39,0)) -> Lakshadweep | D67: =INDEX(Raw_Data!$A$4:$A$39,MATCH(LARGE(Raw_Data!$M$4:$M$39,3),Raw_Data!$M$4:$M$39,0)) -> Mizoram | E67: =INDEX(Raw_Data!$A$4:$A$39,MATCH(LARGE(Raw_Data!$M$4:$M$39,4),Raw_Data!$M$4:$M$39,0)) -> Goa | F67: =INDEX(Raw_Data!$A$4:$A$39,MATCH(LARGE(Raw_Data!$M$4:$M$39,5),Raw_Data!$M$4:$M$39,0)) -> Tripura
A68: Fastest Growing | B68: =INDEX(Raw_Data!$A$4:$A$39,MATCH(LARGE(Raw_Data!$N$4:$N$39,1),Raw_Data!$N$4:$N$39,0)) -> Dadra & NH / DD | C68: =INDEX(Raw_Data!$A$4:$A$39,MATCH(LARGE(Raw_Data!$N$4:$N$39,2),Raw_Data!$N$4:$N$39,0)) -> Manipur | D68: =INDEX(Raw_Data!$A$4:$A$39,MATCH(LARGE(Raw_Data!$N$4:$N$39,3),Raw_Data!$N$4:$N$39,0)) -> Puducherry | E68: =INDEX(Raw_Data!$A$4:$A$39,MATCH(LARGE(Raw_Data!$N$4:$N$39,4),Raw_Data!$N$4:$N$39,0)) -> Meghalaya | F68: =INDEX(Raw_Data!$A$4:$A$39,MATCH(LARGE(Raw_Data!$N$4:$N$39,5),Raw_Data!$N$4:$N$39,0)) -> Arunachal Pradesh
A69: Highest HDI | B69: =INDEX(Raw_Data!$A$4:$A$39,MATCH(LARGE(Raw_Data!$O$4:$O$39,1),Raw_Data!$O$4:$O$39,0)) -> Kerala | C69: =INDEX(Raw_Data!$A$4:$A$39,MATCH(LARGE(Raw_Data!$O$4:$O$39,2),Raw_Data!$O$4:$O$39,0)) -> Chandigarh | D69: =INDEX(Raw_Data!$A$4:$A$39,MATCH(LARGE(Raw_Data!$O$4:$O$39,3),Raw_Data!$O$4:$O$39,0)) -> Goa | E69: =INDEX(Raw_Data!$A$4:$A$39,MATCH(LARGE(Raw_Data!$O$4:$O$39,4),Raw_Data!$O$4:$O$39,0)) -> Maharashtra | F69: =INDEX(Raw_Data!$A$4:$A$39,MATCH(LARGE(Raw_Data!$O$4:$O$39,5),Raw_Data!$O$4:$O$39,0)) -> Delhi

Sheet Pivot_Summary
A1: 📋 PIVOT SUMMARY TABLES | Multi-Dimensional India Population
A3: PIVOT 1 — Population by Region (2001, 2011, 2021)
A4: Region | B4: Pop 2001 | C4: Pop 2011 | D4: Pop 2021* | E4: Growth 01-11 | F4: Growth 11-21
A5: North | B5: =SUMIF(Raw_Data!B:B,A5,Raw_Data!E:E) -> 307671042 | C5: =SUMIF(Raw_Data!B:B,A5,Raw_Data!F:F) -> 369065454 | D5: =SUMIF(Raw_Data!B:B,A5,Raw_Data!G:G) -> 427525000 | E5: =IF(B5>0,(C5-B5)/B5,0) -> 0.19954563 | F5: =IF(C5>0,(D5-C5)/C5,0) -> 0.15839886
A6: South | B6: =SUMIF(Raw_Data!B:B,A6,Raw_Data!E:E) -> 224342617 | C6: =SUMIF(Raw_Data!B:B,A6,Raw_Data!F:F) -> 252351287 | D6: =SUMIF(Raw_Data!B:B,A6,Raw_Data!G:G) -> 275470000 | E6: =IF(B6>0,(C6-B6)/B6,0) -> 0.12484775 | F6: =IF(C6>0,(D6-C6)/C6,0) -> 0.091613216
A7: East | B7: =SUMIF(Raw_Data!B:B,A7,Raw_Data!E:E) -> 227281347 | C7: =SUMIF(Raw_Data!B:B,A7,Raw_Data!F:F) -> 270718500 | D7: =SUMIF(Raw_Data!B:B,A7,Raw_Data!G:G) -> 304420000 | E7: =IF(B7>0,(C7-B7)/B7,0) -> 0.19111622 | F7: =IF(C7>0,(D7-C7)/C7,0) -> 0.12448909
A8: West | B8: =SUMIF(Raw_Data!B:B,A8,Raw_Data!E:E) -> 149117802 | C8: =SUMIF(Raw_Data!B:B,A8,Raw_Data!F:F) -> 174859526 | D8: =SUMIF(Raw_Data!B:B,A8,Raw_Data!G:G) -> 195350000 | E8: =IF(B8>0,(C8-B8)/B8,0) -> 0.17262677 | F8: =IF(C8>0,(D8-C8)/C8,0) -> 0.11718249
A9: Central | B9: =SUMIF(Raw_Data!B:B,A9,Raw_Data!E:E) -> 81181826 | C9: =SUMIF(Raw_Data!B:B,A9,Raw_Data!F:F) -> 98172007 | D9: =SUMIF(Raw_Data!B:B,A9,Raw_Data!G:G) -> 113000000 | E9: =IF(B9>0,(C9-B9)/B9,0) -> 0.20928552 | F9: =IF(C9>0,(D9-C9)/C9,0) -> 0.15104095
A10: Northeast | B10: =SUMIF(Raw_Data!B:B,A10,Raw_Data!E:E) -> 38857769 | C10: =SUMIF(Raw_Data!B:B,A10,Raw_Data!F:F) -> 45772188 | D10: =SUMIF(Raw_Data!B:B,A10,Raw_Data!G:G) -> 51350000 | E10: =IF(B10>0,(C10-B10)/B10,0) -> 0.17794174 | F10: =IF(C10>0,(D10-C10)/C10,0) -> 0.12186029
A11: INDIA TOTAL | B11: =SUM(Raw_Data!E4:RAW4) -> 1.0006359e+09 | C11: =SUM(Raw_Data!F4:RAW4) -> 8.3443794e+08 | D11: =SUM(Raw_Data!G4:RAW4) -> 6.346256e+08 | E11: =IF(B11>0,(C11-B11)/B11,0) -> -0.16609231 | F11: =IF(B11>0,(D11-C11)/C11,0) -> -0.2394574
A13: PIVOT 2 — State vs Union Territory Comparison (2011)
A14: Category | B14: Count | C14: Total Pop | D14: Urban Pop | E14: Rural Pop | F14: Urban % | G14: Avg Literacy | H14: Avg Density
A15: States | B15: =COUNTIF(Raw_Data!C:C,"State") -> 28 | C15: =SUMIF(Raw_Data!C:C,"State",Raw_Data!F:F) -> 1178000017 | D15: =SUMIF(Raw_Data!C:C,"State",Raw_Data!H:H) -> 357057299 | E15: =SUMIF(Raw_Data!C:C,"State",Raw_Data!I:I) -> 820942718 | F15: =IF(C15>0,D15/C15,0) -> 0.30310466 | G15: =AVERAGEIF(Raw_Data!C:C,"State",Raw_Data!M:M) -> 76.467857 | H15: =AVERAGEIF(Raw_Data!C:C,"State",Raw_Data!L:L) -> 371.67857
A16: Union Territories | B16: =COUNTIF(Raw_Data!C:C,"UT") -> 8 | C16: =SUMIF(Raw_Data!C:C,"UT",Raw_Data!F:F) -> 32938945 | D16: =SUMIF(Raw_Data!C:C,"UT",Raw_Data!H:H) -> 22084600 | E16: =SUMIF(Raw_Data!C:C,"UT",Raw_Data!I:I) -> 10854345 | F16: =IF(C16>0,D16/C16,0) -> 0.67047078 | G16: =AVERAGEIF(Raw_Data!C:C,"UT",Raw_Data!M:M) -> 82.6875 | H16: =AVERAGEIF(Raw_Data!C:C,"UT",Raw_Data!L:L) -> 3279.375
A18: PIVOT 3 — States by Literacy Bracket (COUNTIFS / SUMIFS / AVERAGEIFS)
A19: Literacy Range | B19: State Count | C19: Total Pop | D19: Avg Growth Rate | E19: Avg HDI | F19: Urbanization %
A20: 90%+ | B20: =COUNTIFS(Raw_Data!$M$4:$M$39,">=90",Raw_Data!$M$4:$M$39,"<100") -> 3 | C20: =SUMIFS(Raw_Data!$F$4:$F$39,Raw_Data!$M$4:$M$39,">=90",Raw_Data!$M$4:$M$39,"<100") -> 34567740 | D20: =IFERROR(AVERAGEIFS(Raw_Data!$N$4:$N$39,Raw_Data!$M$4:$M$39,">=90",Raw_Data!$M$4:$M$39,"<100"),0) -> 11.566667 | E20: =IFERROR(AVERAGEIFS(Raw_Data!$O$4:$O$39,Raw_Data!$M$4:$M$39,">=90",Raw_Data!$M$4:$M$39,"<100"),0) -> 0.71966667 | F20: =IFERROR(SUMIFS(Raw_Data!$H$4:$H$39,Raw_Data!$M$4:$M$39,">=90",Raw_Data!$M$4:$M$39,"<100")/SUMIFS(Raw_Data!$F$4:$F$39,Raw_Data!$M$4:$M$39,">=90",Raw_Data!$M$4:$M$39,"<100"),0) -> 0.47889373
A21: 80–90% | B21: =COUNTIFS(Raw_Data!$M$4:$M$39,">=80",Raw_Data!$M$4:$M$39,"<90") -> 11 | C21: =SUMIFS(Raw_Data!$F$4:$F$39,Raw_Data!$M$4:$M$39,">=80",Raw_Data!$M$4:$M$39,"<90") -> 218579431 | D21: =IFERROR(AVERAGEIFS(Raw_Data!$N$4:$N$39,Raw_Data!$M$4:$M$39,">=80",Raw_Data!$M$4:$M$39,"<90"),0) -> 13.927273 | E21: =IFERROR(AVERAGEIFS(Raw_Data!$O$4:$O$39,Raw_Data!$M$4:$M$39,">=80",Raw_Data!$M$4:$M$39,"<90"),0) -> 0.71045455 | F21: =IFERROR(SUMIFS(Raw_Data!$H$4:$H$39,Raw_Data!$M$4:$M$39,">=80",Raw_Data!$M$4:$M$39,"<90")/SUMIFS(Raw_Data!$F$4:$F$39,Raw_Data!$M$4:$M$39,">=80",Raw_Data!$M$4:$M$39,"<90"),0) -> 0.49120375
A22: 70–80% | B22: =COUNTIFS(Raw_Data!$M$4:$M$39,">=70",Raw_Data!$M$4:$M$39,"<80") -> 14 | C22: =SUMIFS(Raw_Data!$F$4:$F$39,Raw_Data!$M$4:$M$39,">=70",Raw_Data!$M$4:$M$39,"<80") -> 454027925 | D22: =IFERROR(AVERAGEIFS(Raw_Data!$N$4:$N$39,Raw_Data!$M$4:$M$39,">=70",Raw_Data!$M$4:$M$39,"<80"),0) -> 28.7 | E22: =IFERROR(AVERAGEIFS(Raw_Data!$O$4:$O$39,Raw_Data!$M$4:$M$39,">=70",Raw_Data!$M$4:$M$39,"<80"),0) -> 0.65128571 | F22: =IFERROR(SUMIFS(Raw_Data!$H$4:$H$39,Raw_Data!$M$4:$M$39,">=70",Raw_Data!$M$4:$M$39,"<80")/SUMIFS(Raw_Data!$F$4:$F$39,Raw_Data!$M$4:$M$39,">=70",Raw_Data!$M$4:$M$39,"<80"),0) -> 0.30793662
A23: 60–70% | B23: =COUNTIFS(Raw_Data!$M$4:$M$39,">=60",Raw_Data!$M$4:$M$39,"<70") -> 8 | C23: =SUMIFS(Raw_Data!$F$4:$F$39,Raw_Data!$M$4:$M$39,">=60",Raw_Data!$M$4:$M$39,"<70") -> 503763866 | D23: =IFERROR(AVERAGEIFS(Raw_Data!$N$4:$N$39,Raw_Data!$M$4:$M$39,">=60",Raw_Data!$M$4:$M$39,"<70"),0) -> 16.2375 | E23: =IFERROR(AVERAGEIFS(Raw_Data!$O$4:$O$39,Raw_Data!$M$4:$M$39,">=60",Raw_Data!$M$4:$M$39,"<70"),0) -> 0.62525 | F23: =IFERROR(SUMIFS(Raw_Data!$H$4:$H$39,Raw_Data!$M$4:$M$39,">=60",Raw_Data!$M$4:$M$39,"<70")/SUMIFS(Raw_Data!$F$4:$F$39,Raw_Data!$M$4:$M$39,">=60",Raw_Data!$M$4:$M$39,"<70"),0) -> 0.22909298
A24: Below 60% | B24: =COUNTIFS(Raw_Data!$M$4:$M$39,">=0",Raw_Data!$M$4:$M$39,"<60") -> 0 | C24: =SUMIFS(Raw_Data!$F$4:$F$39,Raw_Data!$M$4:$M$39,">=0",Raw_Data!$M$4:$M$39,"<60") -> 0 | D24: =IFERROR(AVERAGEIFS(Raw_Data!$N$4:$N$39,Raw_Data!$M$4:$M$39,">=0",Raw_Data!$M$4:$M$39,"<60"),0) -> 0 | E24: =IFERROR(AVERAGEIFS(Raw_Data!$O$4:$O$39,Raw_Data!$M$4:$M$39,">=0",Raw_Data!$M$4:$M$39,"<60"),0) -> 0 | F24: =IFERROR(SUMIFS(Raw_Data!$H$4:$H$39,Raw_Data!$M$4:$M$39,">=0",Raw_Data!$M$4:$M$39,"<60")/SUMIFS(Raw_Data!$F$4:$F$39,Raw_Data!$M$4:$M$39,">=0",Raw_Data!$M$4:$M$39,"<60"),0) -> 0

Sheet Charts
A1: 📈 CHARTS & VISUALIZATIONS | India Population Analysis
A3: Top 10 States — Population 2021 | J3: Regional Population 2021
A4: State | B4: Pop 2021 (M) | J4: Region | K4: Pop 2021 (M)
A5: Uttar Pradesh | B5: =VLOOKUP(A5,Raw_Data!A:G,7,FALSE())/1000000 -> 235 | J5: North | K5: =SUMIF(Raw_Data!B:B,J5,Raw_Data!G:G)/1000000 -> 427.525
A6: Maharashtra | B6: =VLOOKUP(A6,Raw_Data!A:G,7,FALSE())/1000000 -> 126 | J6: South | K6: =SUMIF(Raw_Data!B:B,J6,Raw_Data!G:G)/1000000 -> 275.47
A7: Bihar | B7: =VLOOKUP(A7,Raw_Data!A:G,7,FALSE())/1000000 -> 121 | J7: East | K7: =SUMIF(Raw_Data!B:B,J7,Raw_Data!G:G)/1000000 -> 304.42
A8: West Bengal | B8: =VLOOKUP(A8,Raw_Data!A:G,7,FALSE())/1000000 -> 100 | J8: West | K8: =SUMIF(Raw_Data!B:B,J8,Raw_Data!G:G)/1000000 -> 195.35
A9: Madhya Pradesh | B9: =VLOOKUP(A9,Raw_Data!A:G,7,FALSE())/1000000 -> 84 | J9: Central | K9: =SUMIF(Raw_Data!B:B,J9,Raw_Data!G:G)/1000000 -> 113
A10: Rajasthan | B10: =VLOOKUP(A10,Raw_Data!A:G,7,FALSE())/1000000 -> 80 | J10: Northeast | K10: =SUMIF(Raw_Data!B:B,J10,Raw_Data!G:G)/1000000 -> 51.35
A11: Tamil Nadu | B11: =VLOOKUP(A11,Raw_Data!A:G,7,FALSE())/1000000 -> 80
A12: Karnataka | B12: =VLOOKUP(A12,Raw_Data!A:G,7,FALSE())/1000000 -> 68
A13: Gujarat | B13: =VLOOKUP(A13,Raw_Data!A:G,7,FALSE())/1000000 -> 67
A14: Andhra Pradesh | B14: =VLOOKUP(A14,Raw_Data!A:G,7,FALSE())/1000000 -> 52
A20: Urban vs Rural by Region (2011)
A21: Region | B21: Urban (M) | C21: Rural (M)
A22: North | B22: =SUMIF(Raw_Data!B:B,A22,Raw_Data!H:H)/1000000 -> 105.3487 | C22: =SUMIF(Raw_Data!B:B,A22,Raw_Data!I:I)/1000000 -> 263.71675
A23: South | B23: =SUMIF(Raw_Data!B:B,A23,Raw_Data!H:H)/1000000 -> 105.80967 | C23: =SUMIF(Raw_Data!B:B,A23,Raw_Data!I:I)/1000000 -> 146.54162
A24: East | B24: =SUMIF(Raw_Data!B:B,A24,Raw_Data!H:H)/1000000 -> 55.959909 | C24: =SUMIF(Raw_Data!B:B,A24,Raw_Data!I:I)/1000000 -> 214.75859
A25: West | B25: =SUMIF(Raw_Data!B:B,A25,Raw_Data!H:H)/1000000 -> 77.643413 | C25: =SUMIF(Raw_Data!B:B,A25,Raw_Data!I:I)/1000000 -> 97.216113
A26: Central | B26: =SUMIF(Raw_Data!B:B,A26,Raw_Data!H:H)/1000000 -> 25.998028 | C26: =SUMIF(Raw_Data!B:B,A26,Raw_Data!I:I)/1000000 -> 72.173979
A27: NE | B27: =SUMIF(Raw_Data!B:B,A27,Raw_Data!H:H)/1000000 -> 0 | C27: =SUMIF(Raw_Data!B:B,A27,Raw_Data!I:I)/1000000 -> 0

Sheet Dashboard
B1: 🇮🇳 INDIA POPULATION ANALYSIS DASHBOARD | State & UT wise | 2001–2021
B2: 36 States & Union Territories | Census 2001, 2011 | 2021 Projected | Interactive Lookup
B4: 🇮🇳 Total Pop 2021 | D4: 🏙 Urban Pop 2011 | F4: 🌾 Rural Pop 2011 | H4: 📖 Avg Literacy | J4: 📈 Avg Growth Rate | L4: 👥 Avg Density
B6: =TEXT(SUMIF(Raw_Data!A$4:RAW4,"<>",Raw_Data!G$4:RAW4)/1000000000,"0.00")&" B" -> 0.63 B | D6: =TEXT(SUMIF(Raw_Data!A$4:RAW4,"<>",Raw_Data!H$4:RAW4)/1000000,"0")&" M" -> 400 M | F6: =TEXT(SUMIF(Raw_Data!A$4:RAW4,"<>",Raw_Data!I$4:RAW4)/1000000,"0")&" M" -> 355 M | H6: =TEXT(AVERAGEIF(Raw_Data!A$4:RAW4,"<>",Raw_Data!M$4:RAW4),"0.0")&" %" -> 29.5 % | J6: =TEXT(AVERAGEIFS(Raw_Data!N$4:RAW4,Raw_Data!N$4:RAW4,">0"),"0.0")&" %" -> 10.4 % | L6: =TEXT(AVERAGEIF(Raw_Data!A$4:RAW4,"<>",Raw_Data!L$4:RAW4),"0")&" /km²" -> 229 /km²
B9: ▲ Latest Available | D9: ▲ Latest Available | F9: ▲ Latest Available | H9: ▲ Latest Available | J9: ▲ Latest Available | L9: ▲ Latest Available
B11: 🔎 STATE / UT LOOKUP TOOL — Enter any State or UT name below
C12: Enter State/UT: | F12: Kerala
B13: Region | F13: =IFERROR(VLOOKUP(F12,Raw_Data!A:B,2,FALSE()),"Not Found") -> South
B14: Category | F14: =IFERROR(VLOOKUP(F12,Raw_Data!A:C,3,FALSE()),"Not Found") -> State
B15: Area (km²) | F15: =IFERROR(VLOOKUP(F12,Raw_Data!A:D,4,FALSE()),"Not Found") -> 38852
B16: Population 2001 | F16: =IFERROR(VLOOKUP(F12,Raw_Data!A:E,5,FALSE()),"Not Found") -> 31841374
B17: Population 2011 | F17: =IFERROR(VLOOKUP(F12,Raw_Data!A:F,6,FALSE()),"Not Found") -> 33406061
B18: Population 2021* | F18: =IFERROR(VLOOKUP(F12,Raw_Data!A:G,7,FALSE()),"Not Found") -> 35000000
B19: Urban Pop 2011 | F19: =IFERROR(VLOOKUP(F12,Raw_Data!A:H,8,FALSE()),"Not Found") -> 15932171
B20: Rural Pop 2011 | F20: =IFERROR(VLOOKUP(F12,Raw_Data!A:I,9,FALSE()),"Not Found") -> 17473890
B21: Density (/km²) | F21: =IFERROR(VLOOKUP(F12,Raw_Data!A:L,12,FALSE()),"Not Found") -> 860
B22: Literacy % | F22: =IFERROR(VLOOKUP(F12,Raw_Data!A:M,13,FALSE()),"Not Found") -> 94
B23: Growth Rate % | F23: =IFERROR(VLOOKUP(F12,Raw_Data!A:N,14,FALSE()),"Not Found") -> 4.9
B24: HDI Score | F24: =IFERROR(VLOOKUP(F12,Raw_Data!A:O,15,FALSE()),"Not Found") -> 0.782
B25: Capital City | F25: =IFERROR(VLOOKUP(F12,Raw_Data!A:P,16,FALSE()),"Not Found") -> Thiruvananthapuram
B26: Urban % | F26: =IFERROR(VLOOKUP(F12,Raw_Data!A:H,8,FALSE())/VLOOKUP(F12,Raw_Data!A:F,6,FALSE()),"N/A") -> 0.47692456
B29: 📊 REGIONAL POPULATION SUMMARY TABLE (2001 → 2011 → 2021)
B30: Region | C30: Pop 2001 | D30: Pop 2011 | E30: Pop 2021* | F30: Growth 01→11 | G30: Growth 11→21 | H30: Urbanization | I30: Avg Literacy
B31: North | C31: =SUMIF(Raw_Data!B:B,B31,Raw_Data!E:E) -> 307671042 | D31: =SUMIF(Raw_Data!B:B,B31,Raw_Data!F:F) -> 369065454 | E31: =SUMIF(Raw_Data!B:B,B31,Raw_Data!G:G) -> 427525000 | F31: =IF(C31>0,(D31-C31)/C31,0) -> 0.19954563 | G31: =IF(D31>0,(E31-D31)/D31,0) -> 0.15839886 | H31: =IFERROR(SUMIF(Raw_Data!B:B,B31,Raw_Data!H:H)/SUMIF(Raw_Data!B:B,B31,Raw_Data!F:F),0) -> 0.2854472 | I31: =AVERAGEIF(Raw_Data!B:B,B31,Raw_Data!M:M) -> 76.91
B32: South | C32: =SUMIF(Raw_Data!B:B,B32,Raw_Data!E:E) -> 224342617 | D32: =SUMIF(Raw_Data!B:B,B32,Raw_Data!F:F) -> 252351287 | E32: =SUMIF(Raw_Data!B:B,B32,Raw_Data!G:G) -> 275470000 | F32: =IF(C32>0,(D32-C32)/C32,0) -> 0.12484775 | G32: =IF(D32>0,(E32-D32)/D32,0) -> 0.091613216 | H32: =IFERROR(SUMIF(Raw_Data!B:B,B32,Raw_Data!H:H)/SUMIF(Raw_Data!B:B,B32,Raw_Data!F:F),0) -> 0.41929516 | I32: =AVERAGEIF(Raw_Data!B:B,B32,Raw_Data!M:M) -> 80.385714
B33: East | C33: =SUMIF(Raw_Data!B:B,B33,Raw_Data!E:E) -> 227281347 | D33: =SUMIF(Raw_Data!B:B,B33,Raw_Data!F:F) -> 270718500 | E33: =SUMIF(Raw_Data!B:B,B33,Raw_Data!G:G) -> 304420000 | F33: =IF(C33>0,(D33-C33)/C33,0) -> 0.19111622 | G33: =IF(D33>0,(E33-D33)/D33,0) -> 0.12448909 | H33: =IFERROR(SUMIF(Raw_Data!B:B,B33,Raw_Data!H:H)/SUMIF(Raw_Data!B:B,B33,Raw_Data!F:F),0) -> 0.20670885 | I33: =AVERAGEIF(Raw_Data!B:B,B33,Raw_Data!M:M) -> 73.54
B34: West | C34: =SUMIF(Raw_Data!B:B,B34,Raw_Data!E:E) -> 149117802 | D34: =SUMIF(Raw_Data!B:B,B34,Raw_Data!F:F) -> 174859526 | E34: =SUMIF(Raw_Data!B:B,B34,Raw_Data!G:G) -> 195350000 | F34: =IF(C34>0,(D34-C34)/C34,0) -> 0.17262677 | G34: =IF(D34>0,(E34-D34)/D34,0) -> 0.11718249 | H34: =IFERROR(SUMIF(Raw_Data!B:B,B34,Raw_Data!H:H)/SUMIF(Raw_Data!B:B,B34,Raw_Data!F:F),0) -> 0.44403307 | I34: =AVERAGEIF(Raw_Data!B:B,B34,Raw_Data!M:M) -> 81.825
B35: Central | C35: =SUMIF(Raw_Data!B:B,B35,Raw_Data!E:E) -> 81181826 | D35: =SUMIF(Raw_Data!B:B,B35,Raw_Data!F:F) -> 98172007 | E35: =SUMIF(Raw_Data!B:B,B35,Raw_Data!G:G) -> 113000000 | F35: =IF(C35>0,(D35-C35)/C35,0) -> 0.20928552 | G35: =IF(D35>0,(E35-D35)/D35,0) -> 0.15104095 | H35: =IFERROR(SUMIF(Raw_Data!B:B,B35,Raw_Data!H:H)/SUMIF(Raw_Data!B:B,B35,Raw_Data!F:F),0) -> 0.26482119 | I35: =AVERAGEIF(Raw_Data!B:B,B35,Raw_Data!M:M) -> 70.8
B36: Northeast | C36: =SUMIF(Raw_Data!B:B,B36,Raw_Data!E:E) -> 38857769 | D36: =SUMIF(Raw_Data!B:B,B36,Raw_Data!F:F) -> 45772188 | E36: =SUMIF(Raw_Data!B:B,B36,Raw_Data!G:G) -> 51350000 | F36: =IF(C36>0,(D36-C36)/C36,0) -> 0.17794174 | G36: =IF(D36>0,(E36-D36)/D36,0) -> 0.12186029 | H36: =IFERROR(SUMIF(Raw_Data!B:B,B36,Raw_Data!H:H)/SUMIF(Raw_Data!B:B,B36,Raw_Data!F:F),0) -> 0.18312817 | I36: =AVERAGEIF(Raw_Data!B:B,B36,Raw_Data!M:M) -> 79.275
B37: 🇮🇳 INDIA TOTAL | C37: =SUM(Raw_Data!E4:E39) -> 1028452403 | D37: =SUM(Raw_Data!F4:F39) -> 1210938962 | E37: =SUM(Raw_Data!G4:G39) -> 1367115000 | F37: =IF(C37>0,(D37-C37)/C37,0) -> 0.17743802 | G37: =IF(D37>0,(E37-D37)/D37,0) -> 0.12897102 | H37: =IFERROR(SUM(Raw_Data!H4:H39)/SUM(Raw_Data!F4:F39),0) -> 0.31309745 | I37: =AVERAGEIF(Raw_Data!A4:A39,"<>",Raw_Data!M4:M39) -> 77.85
B39: 📚 LITERACY & HDI ANALYSIS (AVERAGEIFS / COUNTIFS)
B40: State | C40: Literacy % | D40: HDI Score | E40: Growth Rate | F40: Density | G40: Classification
B41: Kerala | C41: =IFERROR(VLOOKUP(B41,Raw_Data!A:M,13,FALSE()),"") -> 94 | D41: =IFERROR(VLOOKUP(B41,Raw_Data!A:O,15,FALSE()),"") -> 0.782 | E41: =IFERROR(VLOOKUP(B41,Raw_Data!A:N,14,FALSE()),"") -> 4.9 | F41: =IFERROR(VLOOKUP(B41,Raw_Data!A:L,12,FALSE()),"") -> 860 | G41: =IF(C41>75,"🟢 High Literacy",IF(C41>60,"🟡 Medium","🔴 Low Literacy")) -> 🟢 High Literacy
B42: Mizoram | C42: =IFERROR(VLOOKUP(B42,Raw_Data!A:M,13,FALSE()),"") -> 91.6 | D42: =IFERROR(VLOOKUP(B42,Raw_Data!A:O,15,FALSE()),"") -> 0.7 | E42: =IFERROR(VLOOKUP(B42,Raw_Data!A:N,14,FALSE()),"") -> 23.5 | F42: =IFERROR(VLOOKUP(B42,Raw_Data!A:L,12,FALSE()),"") -> 52 | G42: =IF(C42>75,"🟢 High Literacy",IF(C42>60,"🟡 Medium","🔴 Low Literacy")) -> 🟢 High Literacy
B43: Goa | C43: =IFERROR(VLOOKUP(B43,Raw_Data!A:M,13,FALSE()),"") -> 88.7 | D43: =IFERROR(VLOOKUP(B43,Raw_Data!A:O,15,FALSE()),"") -> 0.761 | E43: =IFERROR(VLOOKUP(B43,Raw_Data!A:N,14,FALSE()),"") -> 8.2 | F43: =IFERROR(VLOOKUP(B43,Raw_Data!A:L,12,FALSE()),"") -> 394 | G43: =IF(C43>75,"🟢 High Literacy",IF(C43>60,"🟡 Medium","🔴 Low Literacy")) -> 🟢 High Literacy
B44: Delhi | C44: =IFERROR(VLOOKUP(B44,Raw_Data!A:M,13,FALSE()),"") -> 86.3 | D44: =IFERROR(VLOOKUP(B44,Raw_Data!A:O,15,FALSE()),"") -> 0.746 | E44: =IFERROR(VLOOKUP(B44,Raw_Data!A:N,14,FALSE()),"") -> 21.2 | F44: =IFERROR(VLOOKUP(B44,Raw_Data!A:L,12,FALSE()),"") -> 11320 | G44: =IF(C44>75,"🟢 High Literacy",IF(C44>60,"🟡 Medium","🔴 Low Literacy")) -> 🟢 High Literacy
B45: Himachal Pradesh | C45: =IFERROR(VLOOKUP(B45,Raw_Data!A:M,13,FALSE()),"") -> 83.8 | D45: =IFERROR(VLOOKUP(B45,Raw_Data!A:O,15,FALSE()),"") -> 0.652 | E45: =IFERROR(VLOOKUP(B45,Raw_Data!A:N,14,FALSE()),"") -> 12.9 | F45: =IFERROR(VLOOKUP(B45,Raw_Data!A:L,12,FALSE()),"") -> 123 | G45: =IF(C45>75,"🟢 High Literacy",IF(C45>60,"🟡 Medium","🔴 Low Literacy")) -> 🟢 High Literacy
B46: Uttarakhand | C46: =IFERROR(VLOOKUP(B46,Raw_Data!A:M,13,FALSE()),"") -> 79.6 | D46: =IFERROR(VLOOKUP(B46,Raw_Data!A:O,15,FALSE()),"") -> 0.684 | E46: =IFERROR(VLOOKUP(B46,Raw_Data!A:N,14,FALSE()),"") -> 19.2 | F46: =IFERROR(VLOOKUP(B46,Raw_Data!A:L,12,FALSE()),"") -> 189 | G46: =IF(C46>75,"🟢 High Literacy",IF(C46>60,"🟡 Medium","🔴 Low Literacy")) -> 🟢 High Literacy
B47: Bihar | C47: =IFERROR(VLOOKUP(B47,Raw_Data!A:M,13,FALSE()),"") -> 63.8 | D47: =IFERROR(VLOOKUP(B47,Raw_Data!A:O,15,FALSE()),"") -> 0.569 | E47: =IFERROR(VLOOKUP(B47,Raw_Data!A:N,14,FALSE()),"") -> 25.4 | F47: =IFERROR(VLOOKUP(B47,Raw_Data!A:L,12,FALSE()),"") -> 1106 | G47: =IF(C47>75,"🟢 High Literacy",IF(C47>60,"🟡 Medium","🔴 Low Literacy")) -> 🟡 Medium
B48: Uttar Pradesh | C48: =IFERROR(VLOOKUP(B48,Raw_Data!A:M,13,FALSE()),"") -> 67.7 | D48: =IFERROR(VLOOKUP(B48,Raw_Data!A:O,15,FALSE()),"") -> 0.596 | E48: =IFERROR(VLOOKUP(B48,Raw_Data!A:N,14,FALSE()),"") -> 20.2 | F48: =IFERROR(VLOOKUP(B48,Raw_Data!A:L,12,FALSE()),"") -> 829 | G48: =IF(C48>75,"🟢 High Literacy",IF(C48>60,"🟡 Medium","🔴 Low Literacy")) -> 🟡 Medium
...

Sheet README
B1: 📘 PROJECT DOCUMENTATION — India Population Data Analysis
B3: ▶ PROJECT OVERVIEW
B4: Project Title : India Population Data Analysis | State & UT wise Census Data
B5: Level : Beginner to Intermediate
B6: Dataset : 36 States & UTs × 16 attributes = 576 data points
B7: Years Covered : Census 2001, Census 2011, Projected 2021
B8: Purpose : Analyze state-wise population, urbanization, literacy, growth & density
B9: Tools Used : Microsoft Excel (No VBA, No Macros, No Power Query)
B10: Data Source : Census of India 2001 & 2011 (Office of Registrar General of India)
B12: ▶ SHEET STRUCTURE
B13: 1. Raw_Data — 36 rows × 16 cols. Data validation (dropdowns + range), conditional formatting, freeze panes
B14: 2. Data_Cleaning — IF/AND/ISNUMBER quality checks. Urban+Rural=Total, gender sum, density validation, status flags
... B94: trajectory — suggesting massive rural-to-urban migration potential in coming decades.
